Workbook

Sheet Sensibilidad
A1: Strategy | B1: Model Sector | C1: Variable Modified ID | D1: BAU | E1: BAI-P | F1: BAI-W | G1: BAI-PM | H1: BAV-OP-P | I1: BAV-OP-W | J1: BAV-OP-PM | K1: BAV-PE-P | L1: BAV-PE-W | M1: BAV-PE-PM
A2: No Strategy Implementation | B2: All | C2: - | D2: •
A3: Production Management (PM) | B3: Production (P) | C3: PIRM | E3: • | G3: • | H3: • | J3: • | K3: • | M3: •
C4: PDRM | E4: • | G4: • | H4: • | J4: • | K4: • | M4: •
C5: PCU | E5: • | G5: • | H5: • | J5: • | K5: • | M5: •
B6: Workers (W) | C6: UW | F6: • | G6: • | I6: • | J6: • | L6: • | M6: •
C7: PMW | F7: • | G7: • | I7: • | J7: • | L7: • | M7: •
A8: Optimistic (OP) | B8: Production (P) | C8: NOr | H8: • | I8: • | J8: •
A9: Pessimistic (PE) | B9: Production (P) | C9: NOr | K9: • | L9: • | M9: •
Q12: Variables asociadas al escenario
Q13: Value | R13: Variable Modified ID | S13: BAU | T13: BAU-P | U13: BAU-W | V13: BAU-PW | W13: OP-P | X13: OP-W | Y13: OP-PW | Z13: PE-P | AA13: PE-W | AB13: PE-PW | AC13: BAU-PE | AD13: BAU-OP
Q14: =Q28 -> 10 | R14: =R28 -> PIRM | S14: =$Q14*S28 -> 10 | T14: =$Q14*T28 -> 20 | U14: =$Q14*U28 -> 10 | V14: =$Q14*V28 -> 20 | W14: =$Q14*W28 -> 20 | X14: =$Q14*X28 -> 10 | Y14: =$Q14*Y28 -> 20 | Z14: =$Q14*Z28 -> 20 | ... AD14: =$Q14*AD28 -> 10
Q15: =Q29 -> 5 | R15: =R29 -> PDRM | S15: =$Q15*S29 -> 5 | T15: =$Q15*T29 -> 10 | U15: =$Q15*U29 -> 5 | V15: =$Q15*V29 -> 10 | W15: =$Q15*W29 -> 10 | X15: =$Q15*X29 -> 5 | Y15: =$Q15*Y29 -> 10 | Z15: =$Q15*Z29 -> 10 | ... AD15: =$Q15*AD29 -> 5
Q16: =Q30 -> 5 | R16: =R30 -> WUP | S16: =$Q16*S30 -> 5 | T16: =$Q16*T30 -> 2.5 | U16: =$Q16*U30 -> 5 | V16: =$Q16*V30 -> 3.75 | W16: =$Q16*W30 -> 2.5 | X16: =$Q16*X30 -> 5 | Y16: =$Q16*Y30 -> 3.75 | Z16: =$Q16*Z30 -> 2.5 | ... AD16: =$Q16*AD30 -> 5
Q17: =Q31 -> 520 | R17: =R31 -> PCU | S17: =$Q17*S31 -> 520 | T17: =$Q17*T31 -> 416 | U17: =$Q17*U31 -> 520 | V17: =$Q17*V31 -> 390 | W17: =$Q17*W31 -> 416 | X17: =$Q17*X31 -> 520 | Y17: =$Q17*Y31 -> 390 | Z17: =$Q17*Z31 -> 416 | ... AD17: =$Q17*AD31 -> 520
Q18: =Q32 -> 1 | R18: =R32 -> STi | S18: =$Q18*S32 -> 1 | T18: =$Q18*T32 -> 1 | U18: =$Q18*U32 -> 1.25 | V18: =$Q18*V32 -> 1.1 | W18: =$Q18*W32 -> 1 | X18: =$Q18*X32 -> 1.25 | Y18: =$Q18*Y32 -> 1.1 | Z18: =$Q18*Z32 -> 1 | ... AD18: =$Q18*AD32 -> 1
Q19: =Q33 -> 20 | R19: =R33 -> UW | S19: =$Q19*S33 -> 20 | T19: =$Q19*T33 -> 24 | U19: =$Q19*U33 -> 16 | V19: =$Q19*V33 -> 20 | W19: =$Q19*W33 -> 24 | X19: =$Q19*X33 -> 16 | Y19: =$Q19*Y33 -> 20 | Z19: =$Q19*Z33 -> 24 | ... AD19: =$Q19*AD33 -> 20
Q20: =Q34 -> 1 | R20: =R34 -> DSCT | S20: =$Q20*S34 -> 1 | T20: =$Q20*T34 -> 1.25 | U20: =$Q20*U34 -> 1 | V20: =$Q20*V34 -> 1.25 | W20: =$Q20*W34 -> 1.25 | X20: =$Q20*X34 -> 1 | Y20: =$Q20*Y34 -> 1.25 | Z20: =$Q20*Z34 -> 1.25 | ... AD20: =$Q20*AD34 -> 1
Q21: =Q35 -> 1.5 | R21: =R35 -> PFCE | S21: =$Q21*S35 -> 1.5 | T21: =$Q21*T35 -> 1.5 | U21: =$Q21*U35 -> 0.75 | V21: =$Q21*V35 -> 1.2 | W21: =$Q21*W35 -> 1.5 | X21: =$Q21*X35 -> 0.75 | Y21: =$Q21*Y35 -> 1.2 | Z21: =$Q21*Z35 -> 1.5 | ... AD21: =$Q21*AD35 -> 1.5
Q22: =Q36 -> 10 | R22: =R36 -> PWCA | S22: =$Q22*S36 -> 10 | T22: =$Q22*T36 -> 10 | U22: =$Q22*U36 -> 15 | V22: =$Q22*V36 -> 12.5 | W22: =$Q22*W36 -> 10 | X22: =$Q22*X36 -> 15 | Y22: =$Q22*Y36 -> 12.5 | Z22: =$Q22*Z36 -> 10 | ... AD22: =$Q22*AD36 -> 10
Q23: =Q37 -> 6.75 | R23: =R37 -> PWD | S23: =$Q23*S37 -> 6.75 | T23: =$Q23*T37 -> 6.75 | U23: =$Q23*U37 -> 3.375 | V23: =$Q23*V37 -> 5.4 | W23: =$Q23*W37 -> 6.75 | X23: =$Q23*X37 -> 3.375 | Y23: =$Q23*Y37 -> 5.4 | Z23: =$Q23*Z37 -> 6.75 | ... AD23: =$Q23*AD37 -> 6.75
Q24: =Q38 -> 59 | R24: =R38 -> PMW | S24: =$Q24*S38 -> 59 | T24: =$Q24*T38 -> 59 | U24: =$Q24*U38 -> 50.15 | V24: =$Q24*V38 -> 53.1 | W24: =$Q24*W38 -> 59 | X24: =$Q24*X38 -> 50.15 | Y24: =$Q24*Y38 -> 53.1 | Z24: =$Q24*Z38 -> 59 | ... AD24: =$Q24*AD38 -> 59
Q25: =Q39 -> 0.5 | R25: =R39 -> Nor | S25: =$Q25*S39 -> 0.5 | T25: =$Q25*T39 -> 0.5 | U25: =$Q25*U39 -> 0.5 | V25: =$Q25*V39 -> 0.5 | W25: =$Q25*W39 -> 1 | X25: =$Q25*X39 -> 1 | Y25: =$Q25*Y39 -> 1 | Z25: =$Q25*Z39 -> -0.5 | ... AD25: =$Q25*AD39 -> 1
Q26: Variación por escenario
Q27: Value | R27: Variable Modified ID | S27: BAU | T27: BAU-P | U27: BAU-W | V27: BAU-PW | W27: OP-P | X27: OP-W | Y27: OP-PW | Z27: PE-P | AA27: PE-W | AB27: PE-PW | AC27: BAU-PE | AD27: BAU-OP
Q28: 10 | R28: PIRM | S28: 1 | T28: 2 | U28: 1 | V28: 2 | W28: 2 | X28: 1 | Y28: 2 | Z28: 2 | AA28: 1 | AB28: 2 | AC28: 1 | AD28: 1
Q29: 5 | R29: PDRM | S29: 1 | T29: 2 | U29: 1 | V29: 2 | W29: 2 | X29: 1 | Y29: 2 | Z29: 2 | AA29: 1 | AB29: 2 | AC29: 1 | AD29: 1
Q30: 5 | R30: WUP | S30: 1 | T30: 0.5 | U30: 1 | V30: 0.75 | W30: 0.5 | X30: 1 | Y30: 0.75 | Z30: 0.5 | AA30: 1 | AB30: 0.75 | AC30: 1 | AD30: 1
Q31: 520 | R31: PCU | S31: 1 | T31: 0.8 | U31: 1 | V31: 0.75 | W31: 0.8 | X31: 1 | Y31: 0.75 | Z31: 0.8 | AA31: 1 | AB31: 0.75 | AC31: 1 | AD31: 1
Q32: 1 | R32: STi | S32: 1 | T32: 1 | U32: 1.25 | V32: 1.1 | W32: 1 | X32: 1.25 | Y32: 1.1 | Z32: 1 | AA32: 1.25 | AB32: 1.1 | AC32: 1 | AD32: 1
Q33: 20 | R33: UW | S33: 1 | T33: 1.2 | U33: 0.8 | V33: 1 | W33: 1.2 | X33: 0.8 | Y33: 1 | Z33: 1.2 | AA33: 0.8 | AB33: 1 | AC33: 1 | AD33: 1
Q34: 1 | R34: DSCT | S34: 1 | T34: 1.25 | U34: 1 | V34: 1.25 | W34: 1.25 | X34: 1 | Y34: 1.25 | Z34: 1.25 | AA34: 1 | AB34: 1.25 | AC34: 1 | AD34: 1
Q35: 1.5 | R35: PFCE | S35: 1 | T35: 1 | U35: 0.5 | V35: 0.8 | W35: 1 | X35: 0.5 | Y35: 0.8 | Z35: 1 | AA35: 0.5 | AB35: 0.8 | AC35: 1 | AD35: 1
Q36: 10 | R36: PWCA | S36: 1 | T36: 1 | U36: 1.5 | V36: 1.25 | W36: 1 | X36: 1.5 | Y36: 1.25 | Z36: 1 | AA36: 1.5 | AB36: 1.25 | AC36: 1 | AD36: 1
Q37: 6.75 | R37: PWD | S37: 1 | T37: 1 | U37: 0.5 | V37: 0.8 | W37: 1 | X37: 0.5 | Y37: 0.8 | Z37: 1 | AA37: 0.5 | AB37: 0.8 | AC37: 1 | AD37: 1
Q38: 59 | R38: PMW | S38: 1 | T38: 1 | U38: 0.85 | V38: 0.9 | W38: 1 | X38: 0.85 | Y38: 0.9 | Z38: 1 | AA38: 0.85 | AB38: 0.9 | AC38: 1 | AD38: 1
Q39: 0.5 | R39: Nor | S39: 1 | T39: 1 | U39: 1 | V39: 1 | W39: 2 | X39: 2 | Y39: 2 | Z39: -1 | AA39: -1 | AB39: -1 | AC39: -1 | AD39: 2
Q42: Value | R42: Variable Modified ID | S42: BAU | T42: BAI-P | U42: BAI-W | V42: BAI-PW | W42: BAV-OP-P | X42: BAV-OP-W | Y42: BAV-OP-PW | Z42: BAV-PE-P | AA42: BAV-PE-W | AB42: BAV-PE-PW
Q43: 10 | R43: PIRM | S43: 1 | T43: 2 | U43: 1 | V43: 2.5 | W43: 2 | X43: 1 | Y43: 2.5 | Z43: 2 | AA43: 1 | AB43: 2.5
Q44: 5 | R44: PDRM | S44: 1 | T44: 2 | U44: 1 | V44: 2.5 | W44: 2 | X44: 1 | Y44: 2.5 | Z44: 2 | AA44: 1 | AB44: 2.5
...

Sheet BAU
A1: Run | B1: BAU | C1: BAU-P | D1: BAU-W | E1: BAU-PW
A2: PIRM | B2: =INDEX(Sensibilidad!$S$14:$AB$25,MATCH($A2,Sensibilidad!$R$14:$R$25,0),MATCH(B$1,Sensibilidad!$S$13:$AB$13,0)) -> 10 | C2: =INDEX(Sensibilidad!$S$14:$AB$25,MATCH($A2,Sensibilidad!$R$14:$R$25,0),MATCH(C$1,Sensibilidad!$S$13:$AB$13,0)) -> 20 | D2: =INDEX(Sensibilidad!$S$14:$AB$25,MATCH($A2,Sensibilidad!$R$14:$R$25,0),MATCH(D$1,Sensibilidad!$S$13:$AB$13,0)) -> 10 | E2: =INDEX(Sensibilidad!$S$14:$AB$25,MATCH($A2,Sensibilidad!$R$14:$R$25,0),MATCH(E$1,Sensibilidad!$S$13:$AB$13,0)) -> 20
A3: PDRM | B3: =INDEX(Sensibilidad!$S$14:$AB$25,MATCH($A3,Sensibilidad!$R$14:$R$25,0),MATCH(B$1,Sensibilidad!$S$13:$AB$13,0)) -> 5 | C3: =INDEX(Sensibilidad!$S$14:$AB$25,MATCH($A3,Sensibilidad!$R$14:$R$25,0),MATCH(C$1,Sensibilidad!$S$13:$AB$13,0)) -> 10 | D3: =INDEX(Sensibilidad!$S$14:$AB$25,MATCH($A3,Sensibilidad!$R$14:$R$25,0),MATCH(D$1,Sensibilidad!$S$13:$AB$13,0)) -> 5 | E3: =INDEX(Sensibilidad!$S$14:$AB$25,MATCH($A3,Sensibilidad!$R$14:$R$25,0),MATCH(E$1,Sensibilidad!$S$13:$AB$13,0)) -> 10
A4: PCU | B4: =INDEX(Sensibilidad!$S$14:$AB$25,MATCH($A4,Sensibilidad!$R$14:$R$25,0),MATCH(B$1,Sensibilidad!$S$13:$AB$13,0)) -> 520 | C4: =INDEX(Sensibilidad!$S$14:$AB$25,MATCH($A4,Sensibilidad!$R$14:$R$25,0),MATCH(C$1,Sensibilidad!$S$13:$AB$13,0)) -> 416 | D4: =INDEX(Sensibilidad!$S$14:$AB$25,MATCH($A4,Sensibilidad!$R$14:$R$25,0),MATCH(D$1,Sensibilidad!$S$13:$AB$13,0)) -> 520 | E4: =INDEX(Sensibilidad!$S$14:$AB$25,MATCH($A4,Sensibilidad!$R$14:$R$25,0),MATCH(E$1,Sensibilidad!$S$13:$AB$13,0)) -> 390
A5: STi | B5: =INDEX(Sensibilidad!$S$14:$AB$25,MATCH($A5,Sensibilidad!$R$14:$R$25,0),MATCH(B$1,Sensibilidad!$S$13:$AB$13,0)) -> 1 | C5: =INDEX(Sensibilidad!$S$14:$AB$25,MATCH($A5,Sensibilidad!$R$14:$R$25,0),MATCH(C$1,Sensibilidad!$S$13:$AB$13,0)) -> 1 | D5: =INDEX(Sensibilidad!$S$14:$AB$25,MATCH($A5,Sensibilidad!$R$14:$R$25,0),MATCH(D$1,Sensibilidad!$S$13:$AB$13,0)) -> 1.25 | E5: =INDEX(Sensibilidad!$S$14:$AB$25,MATCH($A5,Sensibilidad!$R$14:$R$25,0),MATCH(E$1,Sensibilidad!$S$13:$AB$13,0)) -> 1.1
A6: UW | B6: =INDEX(Sensibilidad!$S$14:$AB$25,MATCH($A6,Sensibilidad!$R$14:$R$25,0),MATCH(B$1,Sensibilidad!$S$13:$AB$13,0)) -> 20 | C6: =INDEX(Sensibilidad!$S$14:$AB$25,MATCH($A6,Sensibilidad!$R$14:$R$25,0),MATCH(C$1,Sensibilidad!$S$13:$AB$13,0)) -> 24 | D6: =INDEX(Sensibilidad!$S$14:$AB$25,MATCH($A6,Sensibilidad!$R$14:$R$25,0),MATCH(D$1,Sensibilidad!$S$13:$AB$13,0)) -> 16 | E6: =INDEX(Sensibilidad!$S$14:$AB$25,MATCH($A6,Sensibilidad!$R$14:$R$25,0),MATCH(E$1,Sensibilidad!$S$13:$AB$13,0)) -> 20
A7: DSCT | B7: =INDEX(Sensibilidad!$S$14:$AB$25,MATCH($A7,Sensibilidad!$R$14:$R$25,0),MATCH(B$1,Sensibilidad!$S$13:$AB$13,0)) -> 1 | C7: =INDEX(Sensibilidad!$S$14:$AB$25,MATCH($A7,Sensibilidad!$R$14:$R$25,0),MATCH(C$1,Sensibilidad!$S$13:$AB$13,0)) -> 1.25 | D7: =INDEX(Sensibilidad!$S$14:$AB$25,MATCH($A7,Sensibilidad!$R$14:$R$25,0),MATCH(D$1,Sensibilidad!$S$13:$AB$13,0)) -> 1 | E7: =INDEX(Sensibilidad!$S$14:$AB$25,MATCH($A7,Sensibilidad!$R$14:$R$25,0),MATCH(E$1,Sensibilidad!$S$13:$AB$13,0)) -> 1.25
A8: PFCE | B8: =INDEX(Sensibilidad!$S$14:$AB$25,MATCH($A8,Sensibilidad!$R$14:$R$25,0),MATCH(B$1,Sensibilidad!$S$13:$AB$13,0)) -> 1.5 | C8: =INDEX(Sensibilidad!$S$14:$AB$25,MATCH($A8,Sensibilidad!$R$14:$R$25,0),MATCH(C$1,Sensibilidad!$S$13:$AB$13,0)) -> 1.5 | D8: =INDEX(Sensibilidad!$S$14:$AB$25,MATCH($A8,Sensibilidad!$R$14:$R$25,0),MATCH(D$1,Sensibilidad!$S$13:$AB$13,0)) -> 0.75 | E8: =INDEX(Sensibilidad!$S$14:$AB$25,MATCH($A8,Sensibilidad!$R$14:$R$25,0),MATCH(E$1,Sensibilidad!$S$13:$AB$13,0)) -> 1.2
A9: PWCA | B9: =INDEX(Sensibilidad!$S$14:$AB$25,MATCH($A9,Sensibilidad!$R$14:$R$25,0),MATCH(B$1,Sensibilidad!$S$13:$AB$13,0)) -> 10 | C9: =INDEX(Sensibilidad!$S$14:$AB$25,MATCH($A9,Sensibilidad!$R$14:$R$25,0),MATCH(C$1,Sensibilidad!$S$13:$AB$13,0)) -> 10 | D9: =INDEX(Sensibilidad!$S$14:$AB$25,MATCH($A9,Sensibilidad!$R$14:$R$25,0),MATCH(D$1,Sensibilidad!$S$13:$AB$13,0)) -> 15 | E9: =INDEX(Sensibilidad!$S$14:$AB$25,MATCH($A9,Sensibilidad!$R$14:$R$25,0),MATCH(E$1,Sensibilidad!$S$13:$AB$13,0)) -> 12.5
A10: PWD | B10: =INDEX(Sensibilidad!$S$14:$AB$25,MATCH($A10,Sensibilidad!$R$14:$R$25,0),MATCH(B$1,Sensibilidad!$S$13:$AB$13,0)) -> 6.75 | C10: =INDEX(Sensibilidad!$S$14:$AB$25,MATCH($A10,Sensibilidad!$R$14:$R$25,0),MATCH(C$1,Sensibilidad!$S$13:$AB$13,0)) -> 6.75 | D10: =INDEX(Sensibilidad!$S$14:$AB$25,MATCH($A10,Sensibilidad!$R$14:$R$25,0),MATCH(D$1,Sensibilidad!$S$13:$AB$13,0)) -> 3.375 | E10: =INDEX(Sensibilidad!$S$14:$AB$25,MATCH($A10,Sensibilidad!$R$14:$R$25,0),MATCH(E$1,Sensibilidad!$S$13:$AB$13,0)) -> 5.4
A11: PMW | B11: =INDEX(Sensibilidad!$S$14:$AB$25,MATCH($A11,Sensibilidad!$R$14:$R$25,0),MATCH(B$1,Sensibilidad!$S$13:$AB$13,0)) -> 59 | C11: =INDEX(Sensibilidad!$S$14:$AB$25,MATCH($A11,Sensibilidad!$R$14:$R$25,0),MATCH(C$1,Sensibilidad!$S$13:$AB$13,0)) -> 59 | D11: =INDEX(Sensibilidad!$S$14:$AB$25,MATCH($A11,Sensibilidad!$R$14:$R$25,0),MATCH(D$1,Sensibilidad!$S$13:$AB$13,0)) -> 50.15 | E11: =INDEX(Sensibilidad!$S$14:$AB$25,MATCH($A11,Sensibilidad!$R$14:$R$25,0),MATCH(E$1,Sensibilidad!$S$13:$AB$13,0)) -> 53.1

Sheet BAU-OP-PE
A1: Run | B1: BAU | C1: BAU-PE | D1: BAU-OP
A2: PIRM | B2: =INDEX(Sensibilidad!$S$14:$AD$25,MATCH($A2,Sensibilidad!$R$14:$R$25,0),MATCH(B$1,Sensibilidad!$S$13:$AD$13,0)) -> 10 | C2: =INDEX(Sensibilidad!$S$14:$AD$25,MATCH($A2,Sensibilidad!$R$14:$R$25,0),MATCH(C$1,Sensibilidad!$S$13:$AD$13,0)) -> 10 | D2: =INDEX(Sensibilidad!$S$14:$AD$25,MATCH($A2,Sensibilidad!$R$14:$R$25,0),MATCH(D$1,Sensibilidad!$S$13:$AD$13,0)) -> 10
A3: PDRM | B3: =INDEX(Sensibilidad!$S$14:$AD$25,MATCH($A3,Sensibilidad!$R$14:$R$25,0),MATCH(B$1,Sensibilidad!$S$13:$AD$13,0)) -> 5 | C3: =INDEX(Sensibilidad!$S$14:$AD$25,MATCH($A3,Sensibilidad!$R$14:$R$25,0),MATCH(C$1,Sensibilidad!$S$13:$AD$13,0)) -> 5 | D3: =INDEX(Sensibilidad!$S$14:$AD$25,MATCH($A3,Sensibilidad!$R$14:$R$25,0),MATCH(D$1,Sensibilidad!$S$13:$AD$13,0)) -> 5
A4: PCU | B4: =INDEX(Sensibilidad!$S$14:$AD$25,MATCH($A4,Sensibilidad!$R$14:$R$25,0),MATCH(B$1,Sensibilidad!$S$13:$AD$13,0)) -> 520 | C4: =INDEX(Sensibilidad!$S$14:$AD$25,MATCH($A4,Sensibilidad!$R$14:$R$25,0),MATCH(C$1,Sensibilidad!$S$13:$AD$13,0)) -> 520 | D4: =INDEX(Sensibilidad!$S$14:$AD$25,MATCH($A4,Sensibilidad!$R$14:$R$25,0),MATCH(D$1,Sensibilidad!$S$13:$AD$13,0)) -> 520
A5: STi | B5: =INDEX(Sensibilidad!$S$14:$AD$25,MATCH($A5,Sensibilidad!$R$14:$R$25,0),MATCH(B$1,Sensibilidad!$S$13:$AD$13,0)) -> 1 | C5: =INDEX(Sensibilidad!$S$14:$AD$25,MATCH($A5,Sensibilidad!$R$14:$R$25,0),MATCH(C$1,Sensibilidad!$S$13:$AD$13,0)) -> 1 | D5: =INDEX(Sensibilidad!$S$14:$AD$25,MATCH($A5,Sensibilidad!$R$14:$R$25,0),MATCH(D$1,Sensibilidad!$S$13:$AD$13,0)) -> 1
A6: UW | B6: =INDEX(Sensibilidad!$S$14:$AD$25,MATCH($A6,Sensibilidad!$R$14:$R$25,0),MATCH(B$1,Sensibilidad!$S$13:$AD$13,0)) -> 20 | C6: =INDEX(Sensibilidad!$S$14:$AD$25,MATCH($A6,Sensibilidad!$R$14:$R$25,0),MATCH(C$1,Sensibilidad!$S$13:$AD$13,0)) -> 20 | D6: =INDEX(Sensibilidad!$S$14:$AD$25,MATCH($A6,Sensibilidad!$R$14:$R$25,0),MATCH(D$1,Sensibilidad!$S$13:$AD$13,0)) -> 20
A7: DSCT | B7: =INDEX(Sensibilidad!$S$14:$AD$25,MATCH($A7,Sensibilidad!$R$14:$R$25,0),MATCH(B$1,Sensibilidad!$S$13:$AD$13,0)) -> 1 | C7: =INDEX(Sensibilidad!$S$14:$AD$25,MATCH($A7,Sensibilidad!$R$14:$R$25,0),MATCH(C$1,Sensibilidad!$S$13:$AD$13,0)) -> 1 | D7: =INDEX(Sensibilidad!$S$14:$AD$25,MATCH($A7,Sensibilidad!$R$14:$R$25,0),MATCH(D$1,Sensibilidad!$S$13:$AD$13,0)) -> 1
A8: PFCE | B8: =INDEX(Sensibilidad!$S$14:$AD$25,MATCH($A8,Sensibilidad!$R$14:$R$25,0),MATCH(B$1,Sensibilidad!$S$13:$AD$13,0)) -> 1.5 | C8: =INDEX(Sensibilidad!$S$14:$AD$25,MATCH($A8,Sensibilidad!$R$14:$R$25,0),MATCH(C$1,Sensibilidad!$S$13:$AD$13,0)) -> 1.5 | D8: =INDEX(Sensibilidad!$S$14:$AD$25,MATCH($A8,Sensibilidad!$R$14:$R$25,0),MATCH(D$1,Sensibilidad!$S$13:$AD$13,0)) -> 1.5
A9: PWCA | B9: =INDEX(Sensibilidad!$S$14:$AD$25,MATCH($A9,Sensibilidad!$R$14:$R$25,0),MATCH(B$1,Sensibilidad!$S$13:$AD$13,0)) -> 10 | C9: =INDEX(Sensibilidad!$S$14:$AD$25,MATCH($A9,Sensibilidad!$R$14:$R$25,0),MATCH(C$1,Sensibilidad!$S$13:$AD$13,0)) -> 10 | D9: =INDEX(Sensibilidad!$S$14:$AD$25,MATCH($A9,Sensibilidad!$R$14:$R$25,0),MATCH(D$1,Sensibilidad!$S$13:$AD$13,0)) -> 10
A10: PWD | B10: =INDEX(Sensibilidad!$S$14:$AD$25,MATCH($A10,Sensibilidad!$R$14:$R$25,0),MATCH(B$1,Sensibilidad!$S$13:$AD$13,0)) -> 6.75 | C10: =INDEX(Sensibilidad!$S$14:$AD$25,MATCH($A10,Sensibilidad!$R$14:$R$25,0),MATCH(C$1,Sensibilidad!$S$13:$AD$13,0)) -> 6.75 | D10: =INDEX(Sensibilidad!$S$14:$AD$25,MATCH($A10,Sensibilidad!$R$14:$R$25,0),MATCH(D$1,Sensibilidad!$S$13:$AD$13,0)) -> 6.75
A11: PMW | B11: =INDEX(Sensibilidad!$S$14:$AD$25,MATCH($A11,Sensibilidad!$R$14:$R$25,0),MATCH(B$1,Sensibilidad!$S$13:$AD$13,0)) -> 59 | C11: =INDEX(Sensibilidad!$S$14:$AD$25,MATCH($A11,Sensibilidad!$R$14:$R$25,0),MATCH(C$1,Sensibilidad!$S$13:$AD$13,0)) -> 59 | D11: =INDEX(Sensibilidad!$S$14:$AD$25,MATCH($A11,Sensibilidad!$R$14:$R$25,0),MATCH(D$1,Sensibilidad!$S$13:$AD$13,0)) -> 59
A12: Nor | B12: =INDEX(Sensibilidad!$S$14:$AD$25,MATCH($A12,Sensibilidad!$R$14:$R$25,0),MATCH(B$1,Sensibilidad!$S$13:$AD$13,0)) -> 0.5 | C12: =INDEX(Sensibilidad!$S$14:$AD$25,MATCH($A12,Sensibilidad!$R$14:$R$25,0),MATCH(C$1,Sensibilidad!$S$13:$AD$13,0)) -> -0.5 | D12: =INDEX(Sensibilidad!$S$14:$AD$25,MATCH($A12,Sensibilidad!$R$14:$R$25,0),MATCH(D$1,Sensibilidad!$S$13:$AD$13,0)) -> 1

Sheet BAV-OP
A1: Run | B1: BAU | C1: OP-P | D1: OP-W | E1: OP-PW
A2: PIRM | B2: =INDEX(Sensibilidad!$S$14:$AB$25,MATCH($A2,Sensibilidad!$R$14:$R$25,0),MATCH(B$1,Sensibilidad!$S$13:$AB$13,0)) -> 10 | C2: =INDEX(Sensibilidad!$S$14:$AB$25,MATCH($A2,Sensibilidad!$R$14:$R$25,0),MATCH(C$1,Sensibilidad!$S$13:$AB$13,0)) -> 20 | D2: =INDEX(Sensibilidad!$S$14:$AB$25,MATCH($A2,Sensibilidad!$R$14:$R$25,0),MATCH(D$1,Sensibilidad!$S$13:$AB$13,0)) -> 10 | E2: =INDEX(Sensibilidad!$S$14:$AB$25,MATCH($A2,Sensibilidad!$R$14:$R$25,0),MATCH(E$1,Sensibilidad!$S$13:$AB$13,0)) -> 20
A3: PDRM | B3: =INDEX(Sensibilidad!$S$14:$AB$25,MATCH($A3,Sensibilidad!$R$14:$R$25,0),MATCH(B$1,Sensibilidad!$S$13:$AB$13,0)) -> 5 | C3: =INDEX(Sensibilidad!$S$14:$AB$25,MATCH($A3,Sensibilidad!$R$14:$R$25,0),MATCH(C$1,Sensibilidad!$S$13:$AB$13,0)) -> 10 | D3: =INDEX(Sensibilidad!$S$14:$AB$25,MATCH($A3,Sensibilidad!$R$14:$R$25,0),MATCH(D$1,Sensibilidad!$S$13:$AB$13,0)) -> 5 | E3: =INDEX(Sensibilidad!$S$14:$AB$25,MATCH($A3,Sensibilidad!$R$14:$R$25,0),MATCH(E$1,Sensibilidad!$S$13:$AB$13,0)) -> 10
A4: PCU | B4: =INDEX(Sensibilidad!$S$14:$AB$25,MATCH($A4,Sensibilidad!$R$14:$R$25,0),MATCH(B$1,Sensibilidad!$S$13:$AB$13,0)) -> 520 | C4: =INDEX(Sensibilidad!$S$14:$AB$25,MATCH($A4,Sensibilidad!$R$14:$R$25,0),MATCH(C$1,Sensibilidad!$S$13:$AB$13,0)) -> 416 | D4: =INDEX(Sensibilidad!$S$14:$AB$25,MATCH($A4,Sensibilidad!$R$14:$R$25,0),MATCH(D$1,Sensibilidad!$S$13:$AB$13,0)) -> 520 | E4: =INDEX(Sensibilidad!$S$14:$AB$25,MATCH($A4,Sensibilidad!$R$14:$R$25,0),MATCH(E$1,Sensibilidad!$S$13:$AB$13,0)) -> 390
A5: STi | B5: =INDEX(Sensibilidad!$S$14:$AB$25,MATCH($A5,Sensibilidad!$R$14:$R$25,0),MATCH(B$1,Sensibilidad!$S$13:$AB$13,0)) -> 1 | C5: =INDEX(Sensibilidad!$S$14:$AB$25,MATCH($A5,Sensibilidad!$R$14:$R$25,0),MATCH(C$1,Sensibilidad!$S$13:$AB$13,0)) -> 1 | D5: =INDEX(Sensibilidad!$S$14:$AB$25,MATCH($A5,Sensibilidad!$R$14:$R$25,0),MATCH(D$1,Sensibilidad!$S$13:$AB$13,0)) -> 1.25 | E5: =INDEX(Sensibilidad!$S$14:$AB$25,MATCH($A5,Sensibilidad!$R$14:$R$25,0),MATCH(E$1,Sensibilidad!$S$13:$AB$13,0)) -> 1.1
A6: UW | B6: =INDEX(Sensibilidad!$S$14:$AB$25,MATCH($A6,Sensibilidad!$R$14:$R$25,0),MATCH(B$1,Sensibilidad!$S$13:$AB$13,0)) -> 20 | C6: =INDEX(Sensibilidad!$S$14:$AB$25,MATCH($A6,Sensibilidad!$R$14:$R$25,0),MATCH(C$1,Sensibilidad!$S$13:$AB$13,0)) -> 24 | D6: =INDEX(Sensibilidad!$S$14:$AB$25,MATCH($A6,Sensibilidad!$R$14:$R$25,0),MATCH(D$1,Sensibilidad!$S$13:$AB$13,0)) -> 16 | E6: =INDEX(Sensibilidad!$S$14:$AB$25,MATCH($A6,Sensibilidad!$R$14:$R$25,0),MATCH(E$1,Sensibilidad!$S$13:$AB$13,0)) -> 20
A7: DSCT | B7: =INDEX(Sensibilidad!$S$14:$AB$25,MATCH($A7,Sensibilidad!$R$14:$R$25,0),MATCH(B$1,Sensibilidad!$S$13:$AB$13,0)) -> 1 | C7: =INDEX(Sensibilidad!$S$14:$AB$25,MATCH($A7,Sensibilidad!$R$14:$R$25,0),MATCH(C$1,Sensibilidad!$S$13:$AB$13,0)) -> 1.25 | D7: =INDEX(Sensibilidad!$S$14:$AB$25,MATCH($A7,Sensibilidad!$R$14:$R$25,0),MATCH(D$1,Sensibilidad!$S$13:$AB$13,0)) -> 1 | E7: =INDEX(Sensibilidad!$S$14:$AB$25,MATCH($A7,Sensibilidad!$R$14:$R$25,0),MATCH(E$1,Sensibilidad!$S$13:$AB$13,0)) -> 1.25
A8: PFCE | B8: =INDEX(Sensibilidad!$S$14:$AB$25,MATCH($A8,Sensibilidad!$R$14:$R$25,0),MATCH(B$1,Sensibilidad!$S$13:$AB$13,0)) -> 1.5 | C8: =INDEX(Sensibilidad!$S$14:$AB$25,MATCH($A8,Sensibilidad!$R$14:$R$25,0),MATCH(C$1,Sensibilidad!$S$13:$AB$13,0)) -> 1.5 | D8: =INDEX(Sensibilidad!$S$14:$AB$25,MATCH($A8,Sensibilidad!$R$14:$R$25,0),MATCH(D$1,Sensibilidad!$S$13:$AB$13,0)) -> 0.75 | E8: =INDEX(Sensibilidad!$S$14:$AB$25,MATCH($A8,Sensibilidad!$R$14:$R$25,0),MATCH(E$1,Sensibilidad!$S$13:$AB$13,0)) -> 1.2
A9: PWCA | B9: =INDEX(Sensibilidad!$S$14:$AB$25,MATCH($A9,Sensibilidad!$R$14:$R$25,0),MATCH(B$1,Sensibilidad!$S$13:$AB$13,0)) -> 10 | C9: =INDEX(Sensibilidad!$S$14:$AB$25,MATCH($A9,Sensibilidad!$R$14:$R$25,0),MATCH(C$1,Sensibilidad!$S$13:$AB$13,0)) -> 10 | D9: =INDEX(Sensibilidad!$S$14:$AB$25,MATCH($A9,Sensibilidad!$R$14:$R$25,0),MATCH(D$1,Sensibilidad!$S$13:$AB$13,0)) -> 15 | E9: =INDEX(Sensibilidad!$S$14:$AB$25,MATCH($A9,Sensibilidad!$R$14:$R$25,0),MATCH(E$1,Sensibilidad!$S$13:$AB$13,0)) -> 12.5
A10: PWD | B10: =INDEX(Sensibilidad!$S$14:$AB$25,MATCH($A10,Sensibilidad!$R$14:$R$25,0),MATCH(B$1,Sensibilidad!$S$13:$AB$13,0)) -> 6.75 | C10: =INDEX(Sensibilidad!$S$14:$AB$25,MATCH($A10,Sensibilidad!$R$14:$R$25,0),MATCH(C$1,Sensibilidad!$S$13:$AB$13,0)) -> 6.75 | D10: =INDEX(Sensibilidad!$S$14:$AB$25,MATCH($A10,Sensibilidad!$R$14:$R$25,0),MATCH(D$1,Sensibilidad!$S$13:$AB$13,0)) -> 3.375 | E10: =INDEX(Sensibilidad!$S$14:$AB$25,MATCH($A10,Sensibilidad!$R$14:$R$25,0),MATCH(E$1,Sensibilidad!$S$13:$AB$13,0)) -> 5.4
A11: PMW | B11: =INDEX(Sensibilidad!$S$14:$AB$25,MATCH($A11,Sensibilidad!$R$14:$R$25,0),MATCH(B$1,Sensibilidad!$S$13:$AB$13,0)) -> 59 | C11: =INDEX(Sensibilidad!$S$14:$AB$25,MATCH($A11,Sensibilidad!$R$14:$R$25,0),MATCH(C$1,Sensibilidad!$S$13:$AB$13,0)) -> 59 | D11: =INDEX(Sensibilidad!$S$14:$AB$25,MATCH($A11,Sensibilidad!$R$14:$R$25,0),MATCH(D$1,Sensibilidad!$S$13:$AB$13,0)) -> 50.15 | E11: =INDEX(Sensibilidad!$S$14:$AB$25,MATCH($A11,Sensibilidad!$R$14:$R$25,0),MATCH(E$1,Sensibilidad!$S$13:$AB$13,0)) -> 53.1
A12: Nor | B12: =INDEX(Sensibilidad!$S$14:$AB$25,MATCH($A12,Sensibilidad!$R$14:$R$25,0),MATCH(B$1,Sensibilidad!$S$13:$AB$13,0)) -> 0.5 | C12: =INDEX(Sensibilidad!$S$14:$AB$25,MATCH($A12,Sensibilidad!$R$14:$R$25,0),MATCH(C$1,Sensibilidad!$S$13:$AB$13,0)) -> 1 | D12: =INDEX(Sensibilidad!$S$14:$AB$25,MATCH($A12,Sensibilidad!$R$14:$R$25,0),MATCH(D$1,Sensibilidad!$S$13:$AB$13,0)) -> 1 | E12: =INDEX(Sensibilidad!$S$14:$AB$25,MATCH($A12,Sensibilidad!$R$14:$R$25,0),MATCH(E$1,Sensibilidad!$S$13:$AB$13,0)) -> 1

Sheet BAV-PE
A1: Run | B1: BAU | C1: PE-P | D1: PE-W | E1: PE-PW
A2: PIRM | B2: =INDEX(Sensibilidad!$S$14:$AB$25,MATCH($A2,Sensibilidad!$R$14:$R$25,0),MATCH(B$1,Sensibilidad!$S$13:$AB$13,0)) -> 10 | C2: =INDEX(Sensibilidad!$S$14:$AB$25,MATCH($A2,Sensibilidad!$R$14:$R$25,0),MATCH(C$1,Sensibilidad!$S$13:$AB$13,0)) -> 20 | D2: =INDEX(Sensibilidad!$S$14:$AB$25,MATCH($A2,Sensibilidad!$R$14:$R$25,0),MATCH(D$1,Sensibilidad!$S$13:$AB$13,0)) -> 10 | E2: =INDEX(Sensibilidad!$S$14:$AB$25,MATCH($A2,Sensibilidad!$R$14:$R$25,0),MATCH(E$1,Sensibilidad!$S$13:$AB$13,0)) -> 20
A3: PDRM | B3: =INDEX(Sensibilidad!$S$14:$AB$25,MATCH($A3,Sensibilidad!$R$14:$R$25,0),MATCH(B$1,Sensibilidad!$S$13:$AB$13,0)) -> 5 | C3: =INDEX(Sensibilidad!$S$14:$AB$25,MATCH($A3,Sensibilidad!$R$14:$R$25,0),MATCH(C$1,Sensibilidad!$S$13:$AB$13,0)) -> 10 | D3: =INDEX(Sensibilidad!$S$14:$AB$25,MATCH($A3,Sensibilidad!$R$14:$R$25,0),MATCH(D$1,Sensibilidad!$S$13:$AB$13,0)) -> 5 | E3: =INDEX(Sensibilidad!$S$14:$AB$25,MATCH($A3,Sensibilidad!$R$14:$R$25,0),MATCH(E$1,Sensibilidad!$S$13:$AB$13,0)) -> 10
A4: PCU | B4: =INDEX(Sensibilidad!$S$14:$AB$25,MATCH($A4,Sensibilidad!$R$14:$R$25,0),MATCH(B$1,Sensibilidad!$S$13:$AB$13,0)) -> 520 | C4: =INDEX(Sensibilidad!$S$14:$AB$25,MATCH($A4,Sensibilidad!$R$14:$R$25,0),MATCH(C$1,Sensibilidad!$S$13:$AB$13,0)) -> 416 | D4: =INDEX(Sensibilidad!$S$14:$AB$25,MATCH($A4,Sensibilidad!$R$14:$R$25,0),MATCH(D$1,Sensibilidad!$S$13:$AB$13,0)) -> 520 | E4: =INDEX(Sensibilidad!$S$14:$AB$25,MATCH($A4,Sensibilidad!$R$14:$R$25,0),MATCH(E$1,Sensibilidad!$S$13:$AB$13,0)) -> 390
A5: STi | B5: =INDEX(Sensibilidad!$S$14:$AB$25,MATCH($A5,Sensibilidad!$R$14:$R$25,0),MATCH(B$1,Sensibilidad!$S$13:$AB$13,0)) -> 1 | C5: =INDEX(Sensibilidad!$S$14:$AB$25,MATCH($A5,Sensibilidad!$R$14:$R$25,0),MATCH(C$1,Sensibilidad!$S$13:$AB$13,0)) -> 1 | D5: =INDEX(Sensibilidad!$S$14:$AB$25,MATCH($A5,Sensibilidad!$R$14:$R$25,0),MATCH(D$1,Sensibilidad!$S$13:$AB$13,0)) -> 1.25 | E5: =INDEX(Sensibilidad!$S$14:$AB$25,MATCH($A5,Sensibilidad!$R$14:$R$25,0),MATCH(E$1,Sensibilidad!$S$13:$AB$13,0)) -> 1.1
A6: UW | B6: =INDEX(Sensibilidad!$S$14:$AB$25,MATCH($A6,Sensibilidad!$R$14:$R$25,0),MATCH(B$1,Sensibilidad!$S$13:$AB$13,0)) -> 20 | C6: =INDEX(Sensibilidad!$S$14:$AB$25,MATCH($A6,Sensibilidad!$R$14:$R$25,0),MATCH(C$1,Sensibilidad!$S$13:$AB$13,0)) -> 24 | D6: =INDEX(Sensibilidad!$S$14:$AB$25,MATCH($A6,Sensibilidad!$R$14:$R$25,0),MATCH(D$1,Sensibilidad!$S$13:$AB$13,0)) -> 16 | E6: =INDEX(Sensibilidad!$S$14:$AB$25,MATCH($A6,Sensibilidad!$R$14:$R$25,0),MATCH(E$1,Sensibilidad!$S$13:$AB$13,0)) -> 20
A7: DSCT | B7: =INDEX(Sensibilidad!$S$14:$AB$25,MATCH($A7,Sensibilidad!$R$14:$R$25,0),MATCH(B$1,Sensibilidad!$S$13:$AB$13,0)) -> 1 | C7: =INDEX(Sensibilidad!$S$14:$AB$25,MATCH($A7,Sensibilidad!$R$14:$R$25,0),MATCH(C$1,Sensibilidad!$S$13:$AB$13,0)) -> 1.25 | D7: =INDEX(Sensibilidad!$S$14:$AB$25,MATCH($A7,Sensibilidad!$R$14:$R$25,0),MATCH(D$1,Sensibilidad!$S$13:$AB$13,0)) -> 1 | E7: =INDEX(Sensibilidad!$S$14:$AB$25,MATCH($A7,Sensibilidad!$R$14:$R$25,0),MATCH(E$1,Sensibilidad!$S$13:$AB$13,0)) -> 1.25
A8: PFCE | B8: =INDEX(Sensibilidad!$S$14:$AB$25,MATCH($A8,Sensibilidad!$R$14:$R$25,0),MATCH(B$1,Sensibilidad!$S$13:$AB$13,0)) -> 1.5 | C8: =INDEX(Sensibilidad!$S$14:$AB$25,MATCH($A8,Sensibilidad!$R$14:$R$25,0),MATCH(C$1,Sensibilidad!$S$13:$AB$13,0)) -> 1.5 | D8: =INDEX(Sensibilidad!$S$14:$AB$25,MATCH($A8,Sensibilidad!$R$14:$R$25,0),MATCH(D$1,Sensibilidad!$S$13:$AB$13,0)) -> 0.75 | E8: =INDEX(Sensibilidad!$S$14:$AB$25,MATCH($A8,Sensibilidad!$R$14:$R$25,0),MATCH(E$1,Sensibilidad!$S$13:$AB$13,0)) -> 1.2
A9: PWCA | B9: =INDEX(Sensibilidad!$S$14:$AB$25,MATCH($A9,Sensibilidad!$R$14:$R$25,0),MATCH(B$1,Sensibilidad!$S$13:$AB$13,0)) -> 10 | C9: =INDEX(Sensibilidad!$S$14:$AB$25,MATCH($A9,Sensibilidad!$R$14:$R$25,0),MATCH(C$1,Sensibilidad!$S$13:$AB$13,0)) -> 10 | D9: =INDEX(Sensibilidad!$S$14:$AB$25,MATCH($A9,Sensibilidad!$R$14:$R$25,0),MATCH(D$1,Sensibilidad!$S$13:$AB$13,0)) -> 15 | E9: =INDEX(Sensibilidad!$S$14:$AB$25,MATCH($A9,Sensibilidad!$R$14:$R$25,0),MATCH(E$1,Sensibilidad!$S$13:$AB$13,0)) -> 12.5
A10: PWD | B10: =INDEX(Sensibilidad!$S$14:$AB$25,MATCH($A10,Sensibilidad!$R$14:$R$25,0),MATCH(B$1,Sensibilidad!$S$13:$AB$13,0)) -> 6.75 | C10: =INDEX(Sensibilidad!$S$14:$AB$25,MATCH($A10,Sensibilidad!$R$14:$R$25,0),MATCH(C$1,Sensibilidad!$S$13:$AB$13,0)) -> 6.75 | D10: =INDEX(Sensibilidad!$S$14:$AB$25,MATCH($A10,Sensibilidad!$R$14:$R$25,0),MATCH(D$1,Sensibilidad!$S$13:$AB$13,0)) -> 3.375 | E10: =INDEX(Sensibilidad!$S$14:$AB$25,MATCH($A10,Sensibilidad!$R$14:$R$25,0),MATCH(E$1,Sensibilidad!$S$13:$AB$13,0)) -> 5.4
A11: PMW | B11: =INDEX(Sensibilidad!$S$14:$AB$25,MATCH($A11,Sensibilidad!$R$14:$R$25,0),MATCH(B$1,Sensibilidad!$S$13:$AB$13,0)) -> 59 | C11: =INDEX(Sensibilidad!$S$14:$AB$25,MATCH($A11,Sensibilidad!$R$14:$R$25,0),MATCH(C$1,Sensibilidad!$S$13:$AB$13,0)) -> 59 | D11: =INDEX(Sensibilidad!$S$14:$AB$25,MATCH($A11,Sensibilidad!$R$14:$R$25,0),MATCH(D$1,Sensibilidad!$S$13:$AB$13,0)) -> 50.15 | E11: =INDEX(Sensibilidad!$S$14:$AB$25,MATCH($A11,Sensibilidad!$R$14:$R$25,0),MATCH(E$1,Sensibilidad!$S$13:$AB$13,0)) -> 53.1
A12: Nor | B12: =INDEX(Sensibilidad!$S$14:$AB$25,MATCH($A12,Sensibilidad!$R$14:$R$25,0),MATCH(B$1,Sensibilidad!$S$13:$AB$13,0)) -> 0.5 | C12: =INDEX(Sensibilidad!$S$14:$AB$25,MATCH($A12,Sensibilidad!$R$14:$R$25,0),MATCH(C$1,Sensibilidad!$S$13:$AB$13,0)) -> -0.5 | D12: =INDEX(Sensibilidad!$S$14:$AB$25,MATCH($A12,Sensibilidad!$R$14:$R$25,0),MATCH(D$1,Sensibilidad!$S$13:$AB$13,0)) -> -0.5 | E12: =INDEX(Sensibilidad!$S$14:$AB$25,MATCH($A12,Sensibilidad!$R$14:$R$25,0),MATCH(E$1,Sensibilidad!$S$13:$AB$13,0)) -> -0.5

Sheet BAU-ES
B1: PEFgr | C1: TEF | D1: WEF
A2: Run 1 | B2: 275 | C2: 275 | D2: 275
A3: Run 2 | B3: 162.5 | C3: 387.5 | D3: 162.5
A4: Run 3 | B4: 387.5 | C4: 162.5 | D4: 387.5
A5: Run 4 | B5: 218.75 | C5: 331.25 | D5: 106.25
A6: Run 5 | B6: 443.75 | C6: 106.25 | D6: 331.25
